Traceback (most recent call last):
  File "E:\MainHomePage\.M_HomePage\Lib\site-packages\jupyter_cache\executors\utils.py", line 58, in single_nb_execution
    executenb(
  File "E:\MainHomePage\.M_HomePage\Lib\site-packages\nbclient\client.py", line 1314, in execute
    return NotebookClient(nb=nb, resources=resources, km=km, **kwargs).execute()
           ^^^^^^^^^^^^^^^^^^^^^^^^^^^^^^^^^^^^^^^^^^^^^^^^^^^^^^^^^^^^^^^^^^^^^
  File "E:\MainHomePage\.M_HomePage\Lib\site-packages\jupyter_core\utils\__init__.py", line 165, in wrapped
    return loop.run_until_complete(inner)
           ^^^^^^^^^^^^^^^^^^^^^^^^^^^^^^
  File "C:\Users\Dr\AppData\Local\Programs\Python\Python312\Lib\asyncio\base_events.py", line 687, in run_until_complete
    return future.result()
           ^^^^^^^^^^^^^^^
  File "E:\MainHomePage\.M_HomePage\Lib\site-packages\nbclient\client.py", line 709, in async_execute
    await self.async_execute_cell(
  File "E:\MainHomePage\.M_HomePage\Lib\site-packages\nbclient\client.py", line 1062, in async_execute_cell
    await self._check_raise_for_error(cell, cell_index, exec_reply)
  File "E:\MainHomePage\.M_HomePage\Lib\site-packages\nbclient\client.py", line 918, in _check_raise_for_error
    raise CellExecutionError.from_cell_and_msg(cell, exec_reply_content)
nbclient.exceptions.CellExecutionError: An error occurred while executing the following cell:
------------------
# Import necessary libraries
import PyPDF2
import nltk
import re
import torch
from nltk.tokenize import sent_tokenize
from transformers import pipeline
from sentence_transformers import SentenceTransformer
from sklearn.preprocessing import normalize
from sklearn.metrics.pairwise import cosine_similarity
from google.colab import files
import numpy as np
import os
import gc
------------------


[1;31m---------------------------------------------------------------------------[0m
[1;31mModuleNotFoundError[0m                       Traceback (most recent call last)
Cell [1;32mIn[1], line 2[0m
[0;32m      1[0m [38;5;66;03m# Import necessary libraries[39;00m
[1;32m----> 2[0m [38;5;28;01mimport[39;00m [38;5;21;01mPyPDF2[39;00m
[0;32m      3[0m [38;5;28;01mimport[39;00m [38;5;21;01mnltk[39;00m
[0;32m      4[0m [38;5;28;01mimport[39;00m [38;5;21;01mre[39;00m

[1;31mModuleNotFoundError[0m: No module named 'PyPDF2'

